<?xml version="1.0" encoding="utf-8"?>
<!-- This URDF was automatically created by SolidWorks to URDF Exporter! Originally created by Stephen Brawner (brawner@gmail.com) 
     Commit Version: 1.6.0-1-g15f4949  Build Version: 1.6.7594.29634
     For more information, please see http://wiki.ros.org/sw_urdf_exporter -->
<robot
  name="farhaad">
  <link
    name="base_link">
    <inertial>
      <origin
        xyz="0.031602 1.1884E-17 0.048366"
        rpy="0 0 0" />
      <mass
        value="5" />
      <inertia
        ixx="0.21035"
        ixy="4.2682E-17"
        ixz="0.003449"
        iyy="0.55316"
        iyz="-3.0623E-19"
        izz="0.72715" />
    </inertial>
    <visual>
      <origin
        xyz="0 0 0"
        rpy="0 0 0" />
      <geometry>
        <mesh
          filename="package://farhaad/meshes/base_link.STL" />
      </geometry>
      <material
        name="">
        <color
          rgba="0.79216 0.81961 0.93333 1" />
      </material>
    </visual>
    <collision>
      <origin
        xyz="0 0 0"
        rpy="0 0 0" />
      <geometry>
        <mesh
          filename="package://farhaad/meshes/base_link.STL" />
      </geometry>
    </collision>
  </link>
  <link
    name="Left_Link">
    <inertial>
      <origin
        xyz="2.7756E-17 6.9389E-18 -0.015"
        rpy="0 0 0" />
      <mass
        value="1" />
      <inertia
        ixx="0.0024259"
        ixy="-3.5994E-39"
        ixz="5.8691E-35"
        iyy="0.0024259"
        iyz="-2.7593E-36"
        izz="0.0047119" />
    </inertial>
    <visual>
      <origin
        xyz="0 0 0"
        rpy="0 0 0" />
      <geometry>
        <mesh
          filename="package://farhaad/meshes/Left_Link.STL" />
      </geometry>
      <material
        name="">
        <color
          rgba="0.79216 0.81961 0.93333 1" />
      </material>
    </visual>
    <collision>
      <origin
        xyz="0 0 0"
        rpy="0 0 0" />
      <geometry>
        <mesh
          filename="package://farhaad/meshes/Left_Link.STL" />
      </geometry>
    </collision>
  </link>
  <joint
    name="left_joint"
    type="continuous">
    <origin
      xyz="-0.17 -0.04 0.175"
      rpy="3.1416 0 0" />
    <parent
      link="base_link" />
    <child
      link="Left_Link" />
    <axis
      xyz="0 0 -1" />
  </joint>
  <link
    name="Right_Link">
    <inertial>
      <origin
        xyz="2.7756E-17 6.9389E-18 0.015"
        rpy="0 0 0" />
      <mass
        value="1" />
      <inertia
        ixx="0.0024259"
        ixy="-3.5994E-39"
        ixz="5.8691E-35"
        iyy="0.0024259"
        iyz="-2.7593E-36"
        izz="0.0047119" />
    </inertial>
    <visual>
      <origin
        xyz="0 0 0"
        rpy="0 0 0" />
      <geometry>
        <mesh
          filename="package://farhaad/meshes/Right_Link.STL" />
      </geometry>
      <material
        name="">
        <color
          rgba="0.79216 0.81961 0.93333 1" />
      </material>
    </visual>
    <collision>
      <origin
        xyz="0 0 0"
        rpy="0 0 0" />
      <geometry>
        <mesh
          filename="package://farhaad/meshes/Right_Link.STL" />
      </geometry>
    </collision>
  </link>
  <joint
    name="right_joint"
    type="continuous">
    <origin
      xyz="-0.17 -0.04 -0.175"
      rpy="3.1416 0 0" />
    <parent
      link="base_link" />
    <child
      link="Right_Link" />
    <axis
      xyz="0 0 -1" />
  </joint>
  <gazebo>
    <plugin filename="libgazebo_ros_diff_drive.so" name="differential_drive_controller">
      <alwaysOn>true</alwaysOn>
      <updateRate>20</updateRate>
      <leftJoint>left_joint</leftJoint>
      <rightJoint>right_joint</rightJoint>
      <wheelSeparation>0.350</wheelSeparation>
      <wheelDiameter>0.200</wheelDiameter>
      <torque>5</torque>
      <commandTopic>cmd_vel</commandTopic>
      <odometryTopic>odom</odometryTopic>
      <odometryFrame>odom</odometryFrame>
      <robotBaseFrame>base_link</robotBaseFrame>
    </plugin>
  </gazebo>
</robot>
